<?xml version="1.0" encoding="utf-8"?>
<!-- =================================================================================== -->
<!-- |    This document was autogenerated by xacro from /home/abbas/mars_ws/src/rover_description/urdf/rover.urdf.xacro | -->
<!-- |    EDITING THIS FILE BY HAND IS NOT RECOMMENDED                                 | -->
<!-- =================================================================================== -->
<robot name="rover">
  <gazebo>
    <plugin filename="libgazebo_ros_skid_steer_drive.so" name="skid_steer_drive_controller">
      <updateRate>100.0</updateRate>
      <robotNamespace>/</robotNamespace>
      <leftFrontJoint>front_left_wheel_joint</leftFrontJoint>
      <rightFrontJoint>front_right_wheel_joint</rightFrontJoint>
      <leftRearJoint>back_left_wheel_joint</leftRearJoint>
      <rightRearJoint>back_right_wheel_joint</rightRearJoint>
      <wheelSeparation>0.675</wheelSeparation>
      <wheelDiameter>0.36</wheelDiameter>
      <robotBaseFrame>base_link</robotBaseFrame>
      <torque>7</torque>
      <topicName>cmd_vel</topicName>
      <broadcastTF>true</broadcastTF>
      <odometryTopic>t265_odom_frame</odometryTopic>
      <odometryFrame>t265_odom_frame</odometryFrame>
    </plugin>
  </gazebo>
  <gazebo reference="camera_link">
    <sensor name="depth_camera" type="depth">
      <update_rate>30</update_rate>
      <camera>
        <horizontal_fov>1.047198</horizontal_fov>
        <image>
          <width>640</width>
          <height>480</height>
          <format>R8G8B8</format>
        </image>
        <clip>
          <near>0.05</near>
          <far>3</far>
        </clip>
      </camera>
      <plugin filename="libgazebo_ros_openni_kinect.so" name="camera_controller">
        <baseline>0.2</baseline>
        <alwaysOn>true</alwaysOn>
        <updateRate>1.0</updateRate>
        <cameraName>d400</cameraName>
        <imageTopicName>/camera/depth/image_raw</imageTopicName>
        <cameraInfoTopicName>/camera/depth/camera_info</cameraInfoTopicName>
        <depthImageTopicName>/camera/depth/image_raw</depthImageTopicName>
        <depthImageInfoTopicName>/camera/depth/camera_info</depthImageInfoTopicName>
        <pointCloudTopicName>/d400/depth/color/points</pointCloudTopicName>
        <frameName>camera_link_optical</frameName>
        <pointCloudCutoff>0.105</pointCloudCutoff>
        <pointCloudCutoffMax>7.0</pointCloudCutoffMax>
        <distortionK1>0.00000001</distortionK1>
        <distortionK2>0.00000001</distortionK2>
        <distortionK3>0.00000001</distortionK3>
        <distortionT1>0.00000001</distortionT1>
        <distortionT2>0.00000001</distortionT2>
        <CxPrime>0</CxPrime>
        <Cx>0</Cx>
        <Cy>0</Cy>
        <focalLength>0</focalLength>
        <hackBaseline>0</hackBaseline>
      </plugin>
    </sensor>
  </gazebo>
  <material name="black">
    <color rgba="0.0 0.0 0.0 1.0"/>
  </material>
  <material name="blue">
    <color rgba="0.0 0.0 0.8 1.0"/>
  </material>
  <material name="green">
    <color rgba="0.0 0.8 0.0 1.0"/>
  </material>
  <material name="grey">
    <color rgba="0.2 0.2 0.2 1.0"/>
  </material>
  <material name="orange">
    <color rgba="1.0 0.423529411765 0.0392156862745 1.0"/>
  </material>
  <material name="brown">
    <color rgba="0.870588235294 0.811764705882 0.764705882353 1.0"/>
  </material>
  <material name="red">
    <color rgba="0.8 0.0 0.0 1.0"/>
  </material>
  <material name="white">
    <color rgba="1.0 1.0 1.0 1.0"/>
  </material>
  <!-- <xacro:property name="plateLength" value="0.180"/> <xacro:property name="plateWidth" value="0.25"/> <xacro:property name="plateMass" value="0.267"/> <xacro:property name="plateHeight" value="0.006"/> <xacro:property name="baseHeight"
  value="0.0635"/> <xacro:property name="baseRadius" value="0.12"/> <xacro:property name="arm_link_1Length" value="0.36"/> <xacro:property name="arm_link_2Length" value="0.5"/> <xacro:property name="chassisWidth" value="0.45"/> <xacro:property
  name="baseDamping" value="0.1"/> <xacro:property name="sidePlateLenght" value="0.25"/> <xacro:property name="sidePlateWidth" value="0.05"/> <xacro:property name="sidePlateHeight" value="0.165"/> <xacro:property name="arm_link_1Length" value="0.36"/>
  <xacro:property name="arm_link_1Radius" value="0.08"/> <xacro:property name="sidePlate2arm_link_1Damping" value="0.1"/> <xacro:property name="arm_link_2Length" value="0.5"/> <xacro:property name="arm_link_2Radius" value="0.05"/> <xacro:property
  name="excavatorLenght" value="0.005"/> <xacro:property name="excavatorWidth" value="0.078"/> <xacro:property name="excavatorHeight" value="0.078"/> -->
  <link name="base_link">
    <visual>
      <origin rpy="0 0 0" xyz="0 0 0"/>
      <geometry>
        <box size="0.9 0.6 0.3"/>
      </geometry>
      <material name="green"/>
    </visual>
    <collision>
      <geometry>
        <box size="0.9 0.6 0.3"/>
      </geometry>
    </collision>
    <inertial>
      <mass value="10"/>
      <inertia ixx="1.0" ixy="0.0" ixz="0.0" iyy="1.0" iyz="0.0" izz="1.0"/>
    </inertial>
  </link>
  <link name="front_left_wheel">
    <visual>
      <origin rpy="0 1.57079632679 1.57079632679" xyz="0 0 0"/>
      <!-- Diffrence-->
      <geometry>
        <cylinder length="0.075" radius="0.18"/>
      </geometry>
      <material name="black"/>
    </visual>
    <collision>
      <origin rpy="0 1.57079632679 1.57079632679" xyz="0 0 0"/>
      <geometry>
        <cylinder length="0.075" radius="0.18"/>
      </geometry>
    </collision>
    <inertial>
      <mass value="1"/>
      <inertia ixx="1.0" ixy="0.0" ixz="0.0" iyy="1.0" iyz="0.0" izz="1.0"/>
    </inertial>
  </link>
  <joint name="front_left_wheel_joint" type="continuous">
    <axis rpy="0 0 0" xyz="0 1 0"/>
    <parent link="base_link"/>
    <child link="front_left_wheel"/>
    <origin rpy="0 0 0" xyz="0.3 0.3375 -0.12"/>
  </joint>
  <gazebo reference="front_left_wheel">
    <!-- <mu1 value="0.7"/>
      <mu2 value="0.5"/> -->
    <mu1 value="1"/>
    <mu2 value="1"/>
    <kp value="10000000.0"/>
    <kd value="100.0"/>
    <!-- <! <fdir1 value="1 0 0"/> -> -->
    <material>Gazebo/Black</material>
  </gazebo>
  <transmission name="front_left_trans">
    <type>transmission_interface/SimpleTransmission</type>
    <actuator name="front_left_Motor">
      <mechanicalReduction>1</mechanicalReduction>
    </actuator>
    <joint name="front_left_wheel_joint">
      <hardwareInterface>hardware_interface/VelocityJointInterface</hardwareInterface>
    </joint>
  </transmission>
  <link name="front_right_wheel">
    <visual>
      <origin rpy="0 1.57079632679 1.57079632679" xyz="0 0 0"/>
      <!-- Diffrence-->
      <geometry>
        <cylinder length="0.075" radius="0.18"/>
      </geometry>
      <material name="black"/>
    </visual>
    <collision>
      <origin rpy="0 1.57079632679 1.57079632679" xyz="0 0 0"/>
      <geometry>
        <cylinder length="0.075" radius="0.18"/>
      </geometry>
    </collision>
    <inertial>
      <mass value="1"/>
      <inertia ixx="1.0" ixy="0.0" ixz="0.0" iyy="1.0" iyz="0.0" izz="1.0"/>
    </inertial>
  </link>
  <joint name="front_right_wheel_joint" type="continuous">
    <axis rpy="0 0 0" xyz="0 1 0"/>
    <parent link="base_link"/>
    <child link="front_right_wheel"/>
    <origin rpy="0 0 0" xyz="0.3 -0.3375 -0.12"/>
  </joint>
  <gazebo reference="front_right_wheel">
    <!-- <mu1 value="0.7"/>
      <mu2 value="0.5"/> -->
    <mu1 value="1"/>
    <mu2 value="1"/>
    <kp value="10000000.0"/>
    <kd value="100.0"/>
    <!-- <! <fdir1 value="1 0 0"/> -> -->
    <material>Gazebo/Black</material>
  </gazebo>
  <transmission name="front_right_trans">
    <type>transmission_interface/SimpleTransmission</type>
    <actuator name="front_right_Motor">
      <mechanicalReduction>1</mechanicalReduction>
    </actuator>
    <joint name="front_right_wheel_joint">
      <hardwareInterface>hardware_interface/VelocityJointInterface</hardwareInterface>
    </joint>
  </transmission>
  <link name="back_left_wheel">
    <visual>
      <origin rpy="0 1.57079632679 1.57079632679" xyz="0 0 0"/>
      <!-- Diffrence-->
      <geometry>
        <cylinder length="0.075" radius="0.18"/>
      </geometry>
      <material name="black"/>
    </visual>
    <collision>
      <origin rpy="0 1.57079632679 1.57079632679" xyz="0 0 0"/>
      <geometry>
        <cylinder length="0.075" radius="0.18"/>
      </geometry>
    </collision>
    <inertial>
      <mass value="1"/>
      <inertia ixx="1.0" ixy="0.0" ixz="0.0" iyy="1.0" iyz="0.0" izz="1.0"/>
    </inertial>
  </link>
  <joint name="back_left_wheel_joint" type="continuous">
    <axis rpy="0 0 0" xyz="0 1 0"/>
    <parent link="base_link"/>
    <child link="back_left_wheel"/>
    <origin rpy="0 0 0" xyz="-0.3 0.3375 -0.12"/>
  </joint>
  <gazebo reference="back_left_wheel">
    <!-- <mu1 value="0.7"/>
      <mu2 value="0.5"/> -->
    <mu1 value="1"/>
    <mu2 value="1"/>
    <kp value="10000000.0"/>
    <kd value="100.0"/>
    <!-- <! <fdir1 value="1 0 0"/> -> -->
    <material>Gazebo/Black</material>
  </gazebo>
  <transmission name="back_left_trans">
    <type>transmission_interface/SimpleTransmission</type>
    <actuator name="back_left_Motor">
      <mechanicalReduction>1</mechanicalReduction>
    </actuator>
    <joint name="back_left_wheel_joint">
      <hardwareInterface>hardware_interface/VelocityJointInterface</hardwareInterface>
    </joint>
  </transmission>
  <link name="back_right_wheel">
    <visual>
      <origin rpy="0 1.57079632679 1.57079632679" xyz="0 0 0"/>
      <!-- Diffrence-->
      <geometry>
        <cylinder length="0.075" radius="0.18"/>
      </geometry>
      <material name="black"/>
    </visual>
    <collision>
      <origin rpy="0 1.57079632679 1.57079632679" xyz="0 0 0"/>
      <geometry>
        <cylinder length="0.075" radius="0.18"/>
      </geometry>
    </collision>
    <inertial>
      <mass value="1"/>
      <inertia ixx="1.0" ixy="0.0" ixz="0.0" iyy="1.0" iyz="0.0" izz="1.0"/>
    </inertial>
  </link>
  <joint name="back_right_wheel_joint" type="continuous">
    <axis rpy="0 0 0" xyz="0 1 0"/>
    <parent link="base_link"/>
    <child link="back_right_wheel"/>
    <origin rpy="0 0 0" xyz="-0.3 -0.3375 -0.12"/>
  </joint>
  <gazebo reference="back_right_wheel">
    <!-- <mu1 value="0.7"/>
      <mu2 value="0.5"/> -->
    <mu1 value="1"/>
    <mu2 value="1"/>
    <kp value="10000000.0"/>
    <kd value="100.0"/>
    <!-- <! <fdir1 value="1 0 0"/> -> -->
    <material>Gazebo/Black</material>
  </gazebo>
  <transmission name="back_right_trans">
    <type>transmission_interface/SimpleTransmission</type>
    <actuator name="back_right_Motor">
      <mechanicalReduction>1</mechanicalReduction>
    </actuator>
    <joint name="back_right_wheel_joint">
      <hardwareInterface>hardware_interface/VelocityJointInterface</hardwareInterface>
    </joint>
  </transmission>
  <link name="camera_link">
    <visual>
      <origin rpy="0 0 0" xyz="0 0 0.025"/>
      <geometry>
        <box size="0.05 0.1 0.05"/>
      </geometry>
      <material name="blue"/>
    </visual>
    <collision>
      <origin rpy="0 0 0" xyz="0 0 0.025"/>
      <geometry>
        <box size="0.05 0.1 0.05"/>
      </geometry>
    </collision>
    <inertial>
      <mass value="0.075"/>
      <inertia ixx="1.0" ixy="0.0" ixz="0.0" iyy="1.0" iyz="0.0" izz="1.0"/>
    </inertial>
    <!-- <inertial> <mass value="1e-5"/> <<origin xyz="0 0 0.025" rpy="0 0 0"/> <inertia ixx="1e-6" ixy="0" ixz="0" iyy="1e-6" iyz="0" izz="1e-6"/> </inertial> -->
  </link>
  <joint name="camera_joint" type="fixed">
    <axis rpy="0 0 0" xyz="0 0 0"/>
    <parent link="base_link"/>
    <child link="camera_link"/>
    <origin rpy="0  0 0" xyz="0.65 0 0.35"/>
  </joint>
  <!-- Camera frame rotation fix: https://answers.ros.org/question/232534/gazebo-camera-frame-is-inconsistent-with-rviz-opencv-convention/?answer=232562#post-id-232562 -->
  <joint name="camera_optical_joint" type="fixed">
    <!-- these values have to be these values otherwise the gazebo camera image won't be aligned properly with the frame it is supposedly originating from -->
    <origin rpy="-1.57079632679 0 -1.57079632679" xyz="0 0 0"/>
    <parent link="camera_link"/>
    <child link="camera_link_optical"/>
  </joint>
  <link name="camera_link_optical"/>
  <!-- <joint name="arm_joint_0" type="revolute"> <axis xyz="0 0 1"/> <parent link="base_link"/> <child link="arm_base_link"/> <limit lower="-2" upper="2" effort="1" velocity="2"/> <origin xyz="0 0 ${chassisHeight/2}" rpy="0 0 0"/> </joint> <link
  name="arm_base_link"> <visual> <origin xyz="0 0 ${baseHeight/2}" rpy="0 0 0"/> <geometry> <cylinder length="${baseHeight}" radius="${baseRadius}"/> </geometry> </visual> <inertial> <mass value="${wheelMass}"/> <origin xyz="0 0 ${baseHeight/2}" rpy="0
  0 0"/> <cylinder_inertia m="${wheelMass}" r="${wheelRadius}" h="${wheelWidth}"/> </inertial> <collision> <origin xyz="0 0 ${baseHeight/2}" rpy="0 0 0"/> <geometry> <cylinder length="${baseHeight}" radius="${baseRadius}"/> </geometry> </collision>
  </link> <transmission name="arm_joint_0_trans"> <type>transmission_interface/SimpleTransmission</type> <joint name="arm_joint_0"> <hardwareInterface>PositionJointInterface</hardwareInterface> </joint> <actuator name="arm_joint_0_Motor">
  <hardwareInterface>EffortJointInterface</hardwareInterface> <mechanicalReduction>10</mechanicalReduction> </actuator> </transmission> <joint name="joint_base_side_plate" type="fixed"> <parent link="arm_base_link"/> <child link="side_plate"/> <origin
  xyz="0 0 ${baseHeight}" rpy="0 0 0"/> </joint> <link name="side_plate"> <inertial> <origin xyz="0 0 0" rpy="0 0 0"/> <mass value="0.130"/> <box_inertia m="0.130" x="${sidePlateLenght}" y="${sidePlateWidth}" z="${sidePlateHeight}"/> <box_inertia
  m="0.130" x="${sidePlateLenght}" y="${sidePlateWidth}" z="${sidePlateHeight}"/> </inertial> <visual> <origin xyz="0 0 ${sidePlateHeight/2}" rpy="0 0 0"/> <geometry> <box size="${sidePlateLenght} ${sidePlateWidth} ${sidePlateHeight}"/> </geometry>
  <material name="black"/> </visual> <collision> <origin xyz="0 0 ${sidePlateHeight/2}" rpy="0 0 0"/> <geometry> <box size="${sidePlateLenght} ${sidePlateWidth} ${sidePlateHeight}"/> </geometry> </collision> </link> <transmission
  name="joint_base_side_plate_trans"> <type>transmission_interface/SimpleTransmission</type> <joint name="joint_base_side_plate"> <hardwareInterface>PositionJointInterface</hardwareInterface> </joint> <actuator name="arm_joint_0_Motor">
  <hardwareInterface>EffortJointInterface</hardwareInterface> <mechanicalReduction>10</mechanicalReduction> </actuator> </transmission> <joint name="arm_joint_1" type="revolute"> <parent link="side_plate"/> <child link="arm_link_1"/> <axis xyz=" 0 1
  0"/> <origin xyz="0 0 ${sidePlateHeight}" rpy="0 0 0"/> <dynamics damping="${sidePlate2arm_link_1Damping}"/> <limit effort="100.0" velocity="0.5" lower="-1.571" upper="1.571"/> </joint> <link name="arm_link_1"> <visual> <origin xyz="0 0
  ${arm_link_1Length/2}" rpy="0 0 0"/> <material name="black"/> <geometry> <cylinder length="${arm_link_1Length}" radius="${arm_link_1Radius}"/> </geometry> </visual> <collision> <origin xyz="0 0 ${arm_link_1Length/2}" rpy="0 0 0"/> <geometry>
  <cylinder length="${arm_link_1Length}" radius="${arm_link_1Radius}"/> </geometry> </collision> <inertial> <origin xyz="0.416 0 0.154" rpy="0 0 0"/> <mass value="2"/> <cylinder_inertia m="2" r="${arm_link_1Radius}" h="${arm_link_1Length}"/>
  </inertial> </link> -->
  <!-- <transmission name="arm_link_1_trans"> <type>transmission_interface/SimpleTransmission</type> <joint name="arm_link_1"> <hardwareInterface>PositionJointInterface</hardwareInterface> </joint> <actuator name="arm_link_1_Motor">
  <hardwareInterface>EffortJointInterface</hardwareInterface> <mechanicalReduction>10</mechanicalReduction> </actuator> </transmission> <joint name="arm_joint_2" type="revolute"> <parent link="arm_link_1"/> <child link="arm_link_2"/> <axis xyz=" 0 1
  0"/> <origin xyz="0 0 ${arm_link_1Length}" rpy="0 0 0"/> <dynamics damping="${sidePlate2arm_link_1Damping}"/> <limit effort="100.0" velocity="0.5" lower="-1.571" upper="1.571"/> </joint> <link name="arm_link_2"> <visual> <origin xyz="0 0
  ${arm_link_2Length/2}" rpy="0 0 0"/> <material name="black"/> <geometry> <cylinder length="${arm_link_2Length}" radius="${arm_link_2Radius}"/> </geometry> </visual> <collision> <origin xyz="0 0 ${arm_link_2Length/2}" rpy="0 0 0"/> <geometry>
  <cylinder length="${arm_link_2Length}" radius="${arm_link_2Radius}"/> </geometry> </collision> <inertial> <origin xyz="0.5 0 0.5" rpy="0 0 0"/> <mass value="1"/> <cylinder_inertia m="1" r="${arm_link_2Radius}" h="${arm_link_2Length}"/> </inertial>
  </link> <transmission name="arm_link_2_trans"> <type>transmission_interface/SimpleTransmission</type> <joint name="arm_link_2"> <hardwareInterface>PositionJointInterface</hardwareInterface> </joint> <actuator name="arm_link_2_Motor">
  <hardwareInterface>EffortJointInterface</hardwareInterface> <mechanicalReduction>10</mechanicalReduction> </actuator> </transmission> <joint name="arm_joint_3" type="revolute"> <parent link="arm_link_2"/> <child link="end_effector"/> <axis xyz=" 0 1
  0"/> <origin xyz="0 0 ${arm_link_2Length}" rpy="0 0 0"/> <dynamics damping="${sidePlate2arm_link_1Damping}"/> <limit effort="100.0" velocity="0.5" lower="-1.571" upper="1.571"/> </joint> <link name="end_effector"> <inertial> <origin xyz="0 0 1.0945"
  rpy="0 0 0"/> <mass value="0.1"/> <box_inertia m="0.1" x="${excavatorLenght}" y="${excavatorWidth}" z="${excavatorHeight}"/> </inertial> <visual> <origin xyz="0 0 ${excavatorHeight/2}" rpy="0 0 0"/> <geometry> <box size="${excavatorLenght}
  ${excavatorWidth} ${excavatorHeight}"/> </geometry> <material name="black"/> </visual> <collision> <origin xyz="0 0 ${excavatorHeight/2}" rpy="0 0 0"/> <geometry> <box size="${excavatorLenght} ${excavatorWidth} ${excavatorHeight}"/> </geometry>
  </collision> </link> <transmission name="arm_link_3_trans"> <type>transmission_interface/SimpleTransmission</type> <joint name="arm_link_3"> <hardwareInterface>PositionJointInterface</hardwareInterface> </joint> <actuator name="arm_link_3_Motor">
  <hardwareInterface>EffortJointInterface</hardwareInterface> <mechanicalReduction>10</mechanicalReduction> </actuator> </transmission> -->
</robot>
